<?xml version="1.0" encoding="utf-8"?>
<!-- =================================================================================== -->
<!-- |    This document was autogenerated by xacro from hyqreal.urdf.xacro             | -->
<!-- |    EDITING THIS FILE BY HAND IS NOT RECOMMENDED                                 | -->
<!-- |    @author : Siddharth Deore (sidddharth.deore@iit.it)                          | -->
<!-- =================================================================================== -->

<robot name="hyqreal">

    <material name="grey">
        <color rgba="0.5 0.5 0.5 1" />
    </material>
    <material name="dark_grey">
        <color rgba="0.3 0.3 0.3 1" />
    </material>
    <material name="red">
        <color rgba="1.0 0.0 0.0 1" />
    </material>
    <material name="green">
        <color rgba="0.0 1.0 0.0 1" />
    </material>
    <material name="blue">
        <color rgba="0.13333333333333333 0.25882352941176473 0.7803921568627451 0.1" />
    </material>
    <material name="clr_upper_leg">
        <color rgba="1.0 1.0 0.0 1.0" />
    </material>
    <material name="clr_lower_leg">
        <color rgba="0.3 0.3 0.2 1.0" />
    </material>

    <!-- 
    <joint name="bl_joint" type="fixed">
        <origin rpy="0 0 0" xyz="0 0 0" />
        <parent link="base_link" />
        <child link="trunk" />
    </joint>-->
    
    <joint name="free_joint" type="floating">
        <origin rpy="0 0 0" xyz="0 0 0" />
        <parent link="base_link" />
        <child link="trunk" />
    </joint>
    <!-- -->
    <link name="base_link">
        <inertial>
            <origin xyz="0.0 0.0 0.0" rpy="0.0 0.0 0.0"/>
            <mass value="0.0"/>
            <inertia ixx="0.0" ixy="0.0" ixz="0.0" iyy="0.0" iyz="0.0" izz="0.0"/>
        </inertial>
    </link>
    <!-- Trunk link -->
    <link name="trunk">
        <inertial>
            <origin xyz="-0.015 -0.00186 -0.03465" />
            <mass value="59" />
            <inertia ixx="1.498728" ixy="-0.007369" ixz="-0.189135" iyy="9.492381" iyz="0.000185"
                izz="9.012359" />
        </inertial>
        <visual>
            <origin rpy="0 0 3.14159265359" xyz="0 0 0" />

            <material name="dark_grey" />
            <geometry>
                <mesh filename="assets/combined_torso.stl"
                    scale="0.001 0.001 0.001" />
            </geometry>
        </visual>
        <collision>
            <origin rpy="0 0 3.14159265359" xyz="0 0 0" />

            <geometry>
                <mesh filename="assets/combined_torso.stl"
                    scale="0.001 0.001 0.001" />
            </geometry>
        </collision>
    </link>
    <!-- Links -->
    <!-- Hip assembly link -->
    <link name="lf_hipassembly">
        <inertial>
            <origin xyz="-0.010027 -0.010608 0.003644" />
            <mass value="4.973275" />
            <inertia ixx="0.011231" ixy="-0.000592" ixz="0.000225" iyy="0.015768" iyz="0.000224"
                izz="0.016863" />
        </inertial>
        <visual>
            <origin rpy="0 -1.57079632679 -1.57079632679" xyz="0 -0.046 0" />
            <geometry>

                <cylinder length="0.117" radius="0.0444" />
            </geometry>
        </visual>
    </link>
    <!-- Upper leg link -->
    <link name="lf_upperleg">
        <inertial>
            <origin xyz="0.107987 -0.011459 -0.002121" />
            <mass value="5.877927" />
            <inertia ixx="0.016432" ixy="0.001863" ixz="0.003897" iyy="0.075737" iyz="-0.00024"
                izz="0.079267" />
        </inertial>
        <visual>
            <origin rpy="0 0 0" xyz="0 0 0" />
            <material name="clr_upper_leg" />
            <geometry>
                <mesh filename="assets/upperleg.stl"
                    scale="0.001 0.001 0.001" />
            </geometry>
        </visual>
        <collision>
            <origin rpy="0 0 0" xyz="0 0 0" />
            <material name="clr_upper_leg" />
            <geometry>
                <mesh filename="assets/upperleg.stl"
                    scale="0.001 0.001 0.001" />
            </geometry>
        </collision>
    </link>
    <!-- Lower leg link -->
    <link name="lf_lowerleg">
        <inertial>
            <origin xyz="0.149302 -0.003801 -0.000624" />
            <mass value="1.291954" />
            <inertia ixx="0.001088" ixy="-0.000572" ixz="0.000118" iyy="0.029215" iyz="0.00046"
                izz="0.029772" />
        </inertial>
        <visual>
            <origin rpy="0 0 0" xyz="0 0 0" />

            <geometry>
                <mesh filename="assets/lowerleg.stl"
                    scale="0.001 0.001 0.001" />
            </geometry>
            <material name="clr_lower_leg" />
        </visual>
        <collision>
            <origin rpy="0 0 0" xyz="0 0 0" />

            <geometry>
                <mesh filename="assets/lowerleg.stl"
                    scale="0.001 0.001 0.001" />
            </geometry>
        </collision>
    </link>
    <!-- Foot link -->
    <link name="lf_foot">
        <inertial>
            <origin xyz="0 0 0" />
            <mass value="0.000001" />
            <inertia ixx="0.000001" ixy="0" ixz="0" iyy="0.000001" iyz="0" izz="0.000001" />
        </inertial>
        <visual>
            <origin rpy="0.0 0.0 0.0" xyz="0.0 0.0 0.0" />
            <geometry>
                <sphere radius="0.032" />
            </geometry>
            <material name="black" />
        </visual>
        <collision>
            <origin rpy="0 0 0" xyz="0 0 0" />
            <geometry>
                <sphere radius="0.032" />
            </geometry>
        </collision>
    </link>
    <!-- Links -->
    <!-- Hip assembly link -->
    <link name="rf_hipassembly">
        <inertial>
            <origin xyz="-0.010027 -0.010608 0.003644" />
            <mass value="4.973275" />
            <inertia ixx="0.011231" ixy="-0.000592" ixz="0.000225" iyy="0.015768" iyz="0.000224"
                izz="0.016863" />
        </inertial>
        <visual>
            <origin rpy="0 -1.57079632679 -1.57079632679" xyz="0 -0.046 0" />
            <geometry>

                <cylinder length="0.117" radius="0.0444" />
            </geometry>
        </visual>
    </link>
    <!-- Upper leg link -->
    <link name="rf_upperleg">
        <inertial>
            <origin xyz="0.107987 -0.011459 0.002121" />
            <mass value="5.877927" />
            <inertia ixx="0.016432" ixy="0.001863" ixz="-0.003897" iyy="0.075737" iyz="0.00024"
                izz="0.079267" />
        </inertial>
        <visual>
            <origin rpy="0 0 0" xyz="0 0 0" />
            <material name="clr_upper_leg" />
            <geometry>
                <mesh filename="assets/upperleg.stl"
                    scale="0.001 0.001 0.001" />
            </geometry>
        </visual>
        <collision>
            <origin rpy="0 0 0" xyz="0 0 0" />
            <material name="clr_upper_leg" />
            <geometry>
                <mesh filename="assets/upperleg.stl"
                    scale="0.001 0.001 0.001" />
            </geometry>
        </collision>
    </link>
    <!-- Lower leg link -->
    <link name="rf_lowerleg">
        <inertial>
            <origin xyz="0.149302 -0.003801 -0.000624" />
            <mass value="1.291954" />
            <inertia ixx="0.001088" ixy="-0.000572" ixz="0.000118" iyy="0.029215" iyz="0.00046"
                izz="0.029772" />
        </inertial>
        <visual>
            <origin rpy="0 0 0" xyz="0 0 0" />

            <geometry>
                <mesh filename="assets/lowerleg.stl"
                    scale="0.001 0.001 0.001" />
            </geometry>
            <material name="clr_lower_leg" />
        </visual>
        <collision>
            <origin rpy="0 0 0" xyz="0 0 0" />

            <geometry>
                <mesh filename="assets/lowerleg.stl"
                    scale="0.001 0.001 0.001" />
            </geometry>
        </collision>
    </link>
    <!-- Foot link -->
    <link name="rf_foot">
        <inertial>
            <origin xyz="0 0 0" />
            <mass value="0.000001" />
            <inertia ixx="0.000001" ixy="0" ixz="0" iyy="0.000001" iyz="0" izz="0.000001" />
        </inertial>
        <visual>
            <origin rpy="0.0 0.0 0.0" xyz="0.0 0.0 0.0" />
            <geometry>
                <sphere radius="0.032" />
            </geometry>
            <material name="black" />
        </visual>
        <collision>
            <origin rpy="0 0 0" xyz="0 0 0" />
            <geometry>
                <sphere radius="0.032" />
            </geometry>
        </collision>
    </link>
    <!-- Links -->
    <!-- Hip assembly link -->
    <link name="lh_hipassembly">
        <inertial>
            <origin xyz="-0.010027 -0.010608 0.003644" />
            <mass value="4.973275" />
            <inertia ixx="0.011231" ixy="-0.000592" ixz="0.000225" iyy="0.015768" iyz="0.000224"
                izz="0.016863" />
        </inertial>
        <visual>
            <origin rpy="0 -1.57079632679 -1.57079632679" xyz="0 -0.046 0" />
            <geometry>

                <cylinder length="0.117" radius="0.0444" />
            </geometry>
        </visual>
    </link>
    <!-- Upper leg link -->
    <link name="lh_upperleg">
        <inertial>
            <origin xyz="0.107987 -0.011459 -0.002121" />
            <mass value="5.877927" />
            <inertia ixx="0.016432" ixy="0.001863" ixz="0.003897" iyy="0.075737" iyz="-0.00024"
                izz="0.079267" />
        </inertial>
        <visual>
            <origin rpy="0 0 0" xyz="0 0 0" />
            <material name="clr_upper_leg" />
            <geometry>
                <mesh filename="assets/upperleg.stl"
                    scale="0.001 0.001 0.001" />
            </geometry>
        </visual>
        <collision>
            <origin rpy="0 0 0" xyz="0 0 0" />
            <material name="clr_upper_leg" />
            <geometry>
                <mesh filename="assets/upperleg.stl"
                    scale="0.001 0.001 0.001" />
            </geometry>
        </collision>
    </link>
    <!-- Lower leg link -->
    <link name="lh_lowerleg">
        <inertial>
            <origin xyz="0.149302 -0.003801 -0.000624" />
            <mass value="1.291954" />
            <inertia ixx="0.001088" ixy="-0.000572" ixz="0.000118" iyy="0.029215" iyz="0.00046"
                izz="0.029772" />
        </inertial>
        <visual>
            <origin rpy="0 0 0" xyz="0 0 0" />

            <geometry>
                <mesh filename="assets/lowerleg.stl"
                    scale="0.001 0.001 0.001" />
            </geometry>
            <material name="clr_lower_leg" />
        </visual>
        <collision>
            <origin rpy="0 0 0" xyz="0 0 0" />

            <geometry>
                <mesh filename="assets/lowerleg.stl"
                    scale="0.001 0.001 0.001" />
            </geometry>
        </collision>
    </link>
    <!-- Foot link -->
    <link name="lh_foot">
        <inertial>
            <origin xyz="0 0 0" />
            <mass value="0.000001" />
            <inertia ixx="0.000001" ixy="0" ixz="0" iyy="0.000001" iyz="0" izz="0.000001" />
        </inertial>
        <visual>
            <origin rpy="0.0 0.0 0.0" xyz="0.0 0.0 0.0" />
            <geometry>
                <sphere radius="0.032" />
            </geometry>
            <material name="black" />
        </visual>
        <collision>
            <origin rpy="0 0 0" xyz="0 0 0" />
            <geometry>
                <sphere radius="0.032" />
            </geometry>
        </collision>
    </link>
    <!-- Links -->
    <!-- Hip assembly link -->
    <link name="rh_hipassembly">
        <inertial>
            <origin xyz="-0.010027 -0.010608 0.003644" />
            <mass value="4.973275" />
            <inertia ixx="0.011231" ixy="-0.000592" ixz="0.000225" iyy="0.015768" iyz="0.000224"
                izz="0.016863" />
        </inertial>
        <visual>
            <origin rpy="0 -1.57079632679 -1.57079632679" xyz="0 -0.046 0" />
            <geometry>

                <cylinder length="0.117" radius="0.0444" />
            </geometry>
        </visual>
    </link>
    <!-- Upper leg link -->
    <link name="rh_upperleg">
        <inertial>
            <origin xyz="0.107987 -0.011459 0.002121" />
            <mass value="5.877927" />
            <inertia ixx="0.016432" ixy="0.001863" ixz="-0.003897" iyy="0.075737" iyz="0.00024"
                izz="0.079267" />
        </inertial>
        <visual>
            <origin rpy="0 0 0" xyz="0 0 0" />
            <material name="clr_upper_leg" />
            <geometry>
                <mesh filename="assets/upperleg.stl"
                    scale="0.001 0.001 0.001" />
            </geometry>
        </visual>
        <collision>
            <origin rpy="0 0 0" xyz="0 0 0" />
            <material name="clr_upper_leg" />
            <geometry>
                <mesh filename="assets/upperleg.stl"
                    scale="0.001 0.001 0.001" />
            </geometry>
        </collision>
    </link>
    <!-- Lower leg link -->
    <link name="rh_lowerleg">
        <inertial>
            <origin xyz="0.149302 -0.003801 -0.000624" />
            <mass value="1.291954" />
            <inertia ixx="0.001088" ixy="-0.000572" ixz="0.000118" iyy="0.029215" iyz="0.00046"
                izz="0.029772" />
        </inertial>
        <visual>
            <origin rpy="0 0 0" xyz="0 0 0" />

            <geometry>
                <mesh filename="assets/lowerleg.stl"
                    scale="0.001 0.001 0.001" />
            </geometry>
            <material name="clr_lower_leg" />
        </visual>
        <collision>
            <origin rpy="0 0 0" xyz="0 0 0" />

            <geometry>
                <mesh filename="assets/lowerleg.stl"
                    scale="0.001 0.001 0.001" />
            </geometry>
        </collision>
    </link>
    <!-- Foot link -->
    <link name="rh_foot">
        <inertial>
            <origin xyz="0 0 0" />
            <mass value="0.000001" />
            <inertia ixx="0.000001" ixy="0" ixz="0" iyy="0.000001" iyz="0" izz="0.000001" />
        </inertial>
        <visual>
            <origin rpy="0.0 0.0 0.0" xyz="0.0 0.0 0.0" />
            <geometry>
                <sphere radius="0.032" />
            </geometry>
            <material name="black" />
        </visual>
        <collision>
            <origin rpy="0 0 0" xyz="0 0 0" />
            <geometry>
                <sphere radius="0.032" />
            </geometry>
        </collision>
    </link>


    <!-- Joints -->
    <!-- Joints -->
    <!-- Joints -->
    <!-- Joints -->
    <!-- HAA joint -->
    <joint name="lf_haa_joint" type="revolute">
        <origin rpy="3.14159265359 1.57079632679 0" xyz="0.4435 0.139 0" />
        <parent link="trunk" />
        <child link="lf_hipassembly" />
        <axis xyz="0 0 1" />
        <dynamics damping="0.1" friction="0" />
        <limit effort="173.0" lower="-0.733038285838" upper="0.401425727959" velocity="12.0" />
        <safety_controller k_position="50" k_velocity="10" soft_lower_limit="-0.733038285838"
            soft_upper_limit="0.401425727959" />
    </joint>
    <!-- HFE joint -->
    <joint name="lf_hfe_joint" type="revolute">
        <origin rpy="1.57079632679 0 0" xyz="0 -0.117 0" />
        <parent link="lf_hipassembly" />
        <child link="lf_upperleg" />
        <axis xyz="0 0 1" />
        <dynamics damping="0.1" friction="0" />
        <limit effort="208" lower="0.261799387799" upper="2.18166156499" velocity="12.0" />
        <safety_controller k_position="50" k_velocity="10" soft_lower_limit="0.261799387799"
            soft_upper_limit="2.18166156499" />
    </joint>
    <!-- KFE joint -->
    <joint name="lf_kfe_joint" type="revolute">
        <origin rpy="0 0 0" xyz="0.36 0 0" />
        <parent link="lf_upperleg" />
        <child link="lf_lowerleg" />
        <axis xyz="0 0 1" />
        <dynamics damping="0.1" friction="0" />
        <limit effort="249" lower="-2.77001205584" upper="-0.669857366915" velocity="12.0" />
        <safety_controller k_position="50.0" k_velocity="10.0" soft_lower_limit="-2.77001205584"
            soft_upper_limit="-0.669857366915" />
    </joint>
    <!-- Foot joint -->
    <joint name="lf_foot_joint" type="fixed">
        <origin rpy="1.57079632679 0 -1.57079632679" xyz="0.38 0 0" />
        <parent link="lf_lowerleg" />
        <child link="lf_foot" />
    </joint>
    <!-- HAA joint -->
    <joint name="rf_haa_joint" type="revolute">
        <origin rpy="0 1.57079632679 0" xyz="0.4435 -0.139 0" />
        <parent link="trunk" />
        <child link="rf_hipassembly" />
        <axis xyz="0 0 1" />
        <dynamics damping="0.1" friction="0" />
        <limit effort="173.0" lower="-0.733038285838" upper="0.401425727959" velocity="12.0" />
        <safety_controller k_position="50" k_velocity="10" soft_lower_limit="-0.733038285838"
            soft_upper_limit="0.401425727959" />
    </joint>
    <!-- HFE joint -->
    <joint name="rf_hfe_joint" type="revolute">
        <origin rpy="-1.57079632679 0 0" xyz="0 -0.117 0" />
        <parent link="rf_hipassembly" />
        <child link="rf_upperleg" />
        <axis xyz="0 0 1" />
        <dynamics damping="0.1" friction="0" />
        <limit effort="208" lower="0.261799387799" upper="2.18166156499" velocity="12.0" />
        <safety_controller k_position="50" k_velocity="10" soft_lower_limit="0.261799387799"
            soft_upper_limit="2.18166156499" />
    </joint>
    <!-- KFE joint -->
    <joint name="rf_kfe_joint" type="revolute">
        <origin rpy="0 0 0" xyz="0.36 0 0" />
        <parent link="rf_upperleg" />
        <child link="rf_lowerleg" />
        <axis xyz="0 0 1" />
        <dynamics damping="0.1" friction="0" />
        <limit effort="249" lower="-2.77001205584" upper="-0.669857366915" velocity="12.0" />
        <safety_controller k_position="50.0" k_velocity="10.0" soft_lower_limit="-2.77001205584"
            soft_upper_limit="-0.669857366915" />
    </joint>
    <!-- Foot joint -->
    <joint name="rf_foot_joint" type="fixed">
        <origin rpy="1.57079632679 0 -1.57079632679" xyz="0.38 0 0" />
        <parent link="rf_lowerleg" />
        <child link="rf_foot" />
    </joint>
    <!-- HAA joint -->
    <joint name="lh_haa_joint" type="revolute">
        <origin rpy="3.14159265359 1.57079632679 0" xyz="-0.4435 0.139 0" />
        <parent link="trunk" />
        <child link="lh_hipassembly" />
        <axis xyz="0 0 1" />
        <dynamics damping="0.1" friction="0" />
        <limit effort="173.0" lower="-0.733038285838" upper="0.401425727959" velocity="12.0" />
        <safety_controller k_position="50" k_velocity="10" soft_lower_limit="-0.733038285838"
            soft_upper_limit="0.401425727959" />
    </joint>
    <!-- HFE joint -->
    <joint name="lh_hfe_joint" type="revolute">
        <origin rpy="1.57079632679 0 0" xyz="0 -0.117 0" />
        <parent link="lh_hipassembly" />
        <child link="lh_upperleg" />
        <axis xyz="0 0 1" />
        <dynamics damping="0.1" friction="0" />
        <limit effort="208" lower="0.261799387799" upper="2.18166156499" velocity="12.0" />
        <safety_controller k_position="50" k_velocity="10" soft_lower_limit="0.261799387799"
            soft_upper_limit="2.18166156499" />
    </joint>
    <!-- KFE joint -->
    <joint name="lh_kfe_joint" type="revolute">
        <origin rpy="0 0 0" xyz="0.36 0 0" />
        <parent link="lh_upperleg" />
        <child link="lh_lowerleg" />
        <axis xyz="0 0 1" />
        <dynamics damping="0.1" friction="0" />
        <limit effort="249" lower="-2.77001205584" upper="-0.669857366915" velocity="12.0" />
        <safety_controller k_position="50.0" k_velocity="10.0" soft_lower_limit="-2.77001205584"
            soft_upper_limit="-0.669857366915" />
    </joint>
    <!-- Foot joint -->
    <joint name="lh_foot_joint" type="fixed">
        <origin rpy="1.57079632679 0 -1.57079632679" xyz="0.38 0 0" />
        <parent link="lh_lowerleg" />
        <child link="lh_foot" />
    </joint>
    <!-- HAA joint -->
    <joint name="rh_haa_joint" type="revolute">
        <origin rpy="0 1.57079632679 0" xyz="-0.4435 -0.139 0" />
        <parent link="trunk" />
        <child link="rh_hipassembly" />
        <axis xyz="0 0 1" />
        <dynamics damping="0.1" friction="0" />
        <limit effort="173.0" lower="-0.733038285838" upper="0.401425727959" velocity="12.0" />
        <safety_controller k_position="50" k_velocity="10" soft_lower_limit="-0.733038285838"
            soft_upper_limit="0.401425727959" />
    </joint>
    <!-- HFE joint -->
    <joint name="rh_hfe_joint" type="revolute">
        <origin rpy="-1.57079632679 0 0" xyz="0 -0.117 0" />
        <parent link="rh_hipassembly" />
        <child link="rh_upperleg" />
        <axis xyz="0 0 1" />
        <dynamics damping="0.1" friction="0" />
        <limit effort="208" lower="0.261799387799" upper="2.18166156499" velocity="12.0" />
        <safety_controller k_position="50" k_velocity="10" soft_lower_limit="0.261799387799"
            soft_upper_limit="2.18166156499" />
    </joint>
    <!-- KFE joint -->
    <joint name="rh_kfe_joint" type="revolute">
        <origin rpy="0 0 0" xyz="0.36 0 0" />
        <parent link="rh_upperleg" />
        <child link="rh_lowerleg" />
        <axis xyz="0 0 1" />
        <dynamics damping="0.1" friction="0" />
        <limit effort="249" lower="-2.77001205584" upper="-0.669857366915" velocity="12.0" />
        <safety_controller k_position="50.0" k_velocity="10.0" soft_lower_limit="-2.77001205584"
            soft_upper_limit="-0.669857366915" />
    </joint>
    <!-- Foot joint -->
    <joint name="rh_foot_joint" type="fixed">
        <origin rpy="1.57079632679 0 -1.57079632679" xyz="0.38 0 0" />
        <parent link="rh_lowerleg" />
        <child link="rh_foot" />
    </joint>
    <mujoco>
        <compiler angle="radian" autolimits="true" meshdir="assets" />
    </mujoco>
</robot>